Workbook

Sheet Dashboard
A1: KSHIPRA COMMERCE-REWARD MODEL DASHBOARD
A3: KEY METRICS
A4: Monthly Revenue: | B4: =Calculations!B9 | C4: Total income (bags + ads)
A5: Monthly Margin: | B5: =Calculations!B14 | C5: Final profit after all costs
A6: Margin %: | B6: =Calculations!B14/Calculations!B9 | C6: Profitability ratio
A8: User Net Bag Cost: | B8: =Calculations!B28 | C8: Negative = FREE bags!
A10: 📝 Edit assumptions in the 'Assumptions' sheet (yellow cells)

Sheet Assumptions
A1: KSHIPRA COMMERCE-REWARD MODEL - ASSUMPTIONS
A3: PRICING & VOLUME
A4: Bag Retail Price | B4: 0.4 | C4: $ | D4: What users pay upfront for each bag
A5: Bags Sold per Month | B5: 10000 | C5: bags | D5: Monthly volume - scale this to model growth
A7: AD ECONOMICS
A8: CPV - Brand Pays per View | B8: 0.2 | C8: $ | D8: Revenue per verified ad view (100% engagement)
A9: Cash Credit per View | B9: 0.06 | C9: $ | D9: Instant cash reward to user (goes to wallet)
A10: Reward Points per View | B10: 0.06 | C10: $ | D10: Store credit reward (redeemable at partner stores)
A11: Kshipra Margin per View | B11: 0.08 | C11: $ | D11: Our profit per ad = CPV - Cash - Rewards
A13: USER ENGAGEMENT
A14: Active User Rate | B14: 60 | C14: % | D14: % of buyers who actually watch ads to earn rewards
A16: USER BEHAVIOR
A17: Avg Ads to Recover Bag Cost | B17: 3 | C17: ads | D17: How many ads needed to make bag FREE
A18: Avg Monthly Ad Views per User | B18: 12 | C18: views | D18: Engagement level: ads watched per active user/month
A20: TIER CASH CREDIT LIMITS
A21: Bronze - Bag Values/Month | B21: 1 | D21: Low-engagement: 1 bag purchase/month
A22: Silver - Bag Values/Month | B22: 3 | D22: Medium-engagement: 3 bags/month
A23: Gold - Bag Values/Month | B23: 7 | D23: High-engagement: 7 bags/month
A24: Platinum - Daily Cap ($) | B24: 1 | D24: Super users: $1/day earning limit
A26: USER DISTRIBUTION BY TIER (%)
A27: Bronze % | B27: 60 | C27: % | D27: Most users are casual shoppers
A28: Silver % | B28: 25 | C28: % | D28: Regular shoppers
A29: Gold % | B29: 12 | C29: % | D29: Frequent shoppers
A30: Platinum % | B30: 3 | C30: % | D30: Power users (heavy engagement)
A32: STORE & REDEMPTION METRICS
A33: Reward Redemption Rate | B33: 75 | C33: % | D33: % of users who redeem rewards at stores
A34: Repeat Visit Increase | B34: 15 | C34: % | D34: Users visit more often to use rewards
A35: Basket Size Uplift | B35: 8 | C35: % | D35: Users buy more when they have rewards
A36: Average Basket Value | B36: 25 | C36: $ | D36: Typical purchase amount per store visit
A38: BRAND BENCHMARKS
A39: Meta CPM | B39: 10 | C39: $ | D39: Facebook/Instagram ad cost per 1000 impressions
A40: TikTok CPM | B40: 8.5 | C40: $ | D40: TikTok ad cost per 1000 impressions
A41: Industry Avg CTR | B41: 1 | C41: % | D41: Click-through rate on social media ads (only 1% engage!)

Sheet Calculations
A1: DETAILED CALCULATIONS
A3: MONTHLY BUSINESS SUMMARY
A4: Bags Sold | B4: =Assumptions!B5 | C4: Number of bags purchased this month
A5: Active Users (Watching Ads) | B5: =Assumptions!B5*Assumptions!B14/100 | C5: Users who actually engage with ads
A6: Bag Revenue | B6: =Assumptions!B5*Assumptions!B4 | C6: Income from selling bags to users
A7: Total Ad Views | B7: =B5*Assumptions!B18 | C7: Total verified ad impressions delivered (only active users)
A8: Ad Revenue (Brand Spend) | B8: =B7*Assumptions!B8 | C8: What brands pay for all ad views
A9: Total Revenue | B9: =B6+B8 | C9: Combined income from bags + ads
A11: Total Cash Credits Paid | B11: =B7*Assumptions!B9 | C11: Instant cash rewards given to users
A12: Total Reward Points Issued | B12: =B7*Assumptions!B10 | C12: Store credit rewards issued to users
A13: Gross Margin (from Ads) | B13: =B7*Assumptions!B11 | C13: Profit after paying out all rewards
A14: Total Margin | B14: =B6+B13 | C14: Final profit: bag sales + ad margins
A15: Margin % | B15: =B14/B9 | C15: Profit as percentage of revenue
A17: PER USER METRICS
A18: Monthly Ad Views | B18: =Assumptions!B18 | C18: How many ads each user watches per month
A19: Brand Spend per User | B19: =Assumptions!B18*Assumptions!B8 | C19: Total brands pay for this user's ad views
A20: User Rewards per Month | B20: =Assumptions!B18*(Assumptions!B9+Assumptions!B10) | C20: Cash + reward points user earns monthly
A21: Kshipra Margin per User | B21: =Assumptions!B18*Assumptions!B11 | C21: Our profit per active user per month
A23: PER BAG METRICS
A24: Bag Retail Revenue | B24: =Assumptions!B4 | C24: What users pay for each bag
A25: Ad Views per Bag | B25: =Assumptions!B17 | C25: Ads needed to watch to recover bag cost
A26: Brand Revenue per Bag | B26: =Assumptions!B17*Assumptions!B8 | C26: What brands pay for ads on one bag
A27: User Earnings per Bag | B27: =Assumptions!B17*(Assumptions!B9+Assumptions!B10) | C27: Rewards user gets from watching ads
A28: User Net Cost | B28: =Assumptions!B4-B27 | C28: Final cost after earning rewards (FREE if negative!)
A30: STORE VALUE METRICS
A31: Total Rewards Generated | B31: =B7*(Assumptions!B9+Assumptions!B10) | C31: All rewards earned by users this month
A32: Reward Redemption Value | B32: =B31*Assumptions!B33/100 | C32: How much will actually be redeemed at stores
A33: Estimated Transactions | B33: =Assumptions!B5*Assumptions!B33/100 | C33: Number of store visits to redeem rewards
A34: Baseline Basket Value | B34: =B33*Assumptions!B36 | C34: Total sales if customers buy average basket
A35: Incremental Basket Value | B35: =B34*Assumptions!B35/100 | C35: Extra sales from customers buying more
A37: BRAND ROI COMPARISON
A38: KSHIPRA APPROACH
A39: BagBuddy CPM | B39: =Assumptions!B8*1000 | C39: Cost per 1000 verified ad views (100% engagement)
A40: BagBuddy Cost per Engagement | B40: =Assumptions!B8 | C40: Every view is 100% verified engagement
A41: Cost per Basket Influenced | B41: =B8/B33 | C41: Brand spend per store transaction driven
A43: TRADITIONAL SOCIAL MEDIA (Meta/Facebook)
A44: Meta CPM | B44: =Assumptions!B39 | C44: Cost per 1000 impressions (not engagements!)
A45: Meta CTR | B45: =Assumptions!B41 | C45: Only 1% of viewers click/engage
A46: Meta Cost per Engagement | B46: =(Assumptions!B39/1000)/(Assumptions!B41/100) | C46: True cost accounting for low engagement
A48: KSHIPRA VS META SAVINGS
...

Sheet Scenarios
A1: SCENARIO COMPARISON
A3: Metric | B3: Worst Case | C3: Base Case | D3: Best Case | E3: Unit
A4: Monthly Revenue | B4: 11200 | C4: 18400 | D4: 28000 | E4: $ | F4: Bags + ad revenue combined
A5: Monthly Margin | B5: 6880 | C5: 9760 | D5: 13600 | E5: $ | F5: Final profit after paying users
A6: Margin % | B6: 0.61428571 | C6: 0.53043478 | D6: 0.48571429 | E6: % | F6: Profit as % of revenue
A7: Total Ad Views | B7: 36000 | C7: 72000 | D7: 120000 | E7: views | F7: Verified ad impressions delivered
A9: Store Value Created | B9: 4410 | C9: 15480 | D9: 31365 | E9: $ | F9: Traffic driven to partner stores
A10: Reward Redemptions | B10: 2160 | C10: 6480 | D10: 12240 | E10: $ | F10: Value of rewards redeemed
A12: KEY ASSUMPTION DIFFERENCES
A13: Avg Monthly Ad Views/User | B13: 6 | C13: 12 | D13: 20 | F13: User engagement level
A14: Platinum Users % | B14: 1 | C14: 3 | D14: 8 | E14: % | F14: Power user distribution
A15: Redemption Rate % | B15: 50 | C15: 75 | D15: 85 | E15: % | F15: Users visiting stores to redeem

Sheet Investor Metrics
A1: INVESTOR METRICS
A3: UNIT ECONOMICS
A4: Customer Acquisition Cost (CAC) | B4: 2 | C4: Cost to acquire one new user (marketing)
A5: Avg User Lifetime (months) | B5: 12 | C5: How long users stay active
A7: LIFETIME VALUE (LTV) CALCULATION
A8: LTV from Bag Sales | B8: =B5*(Assumptions!B4) | C8: Lifetime * monthly bag revenue
A9: LTV from Ad Revenue | B9: =B5*Assumptions!B18*Assumptions!B11 | C9: Lifetime * monthly ad margin
A10: Total LTV | B10: =B8+B9 | C10: Total value per user over lifetime
A12: KEY RATIOS
A13: LTV:CAC Ratio | B13: =B10/B4 | C13: >3x = Good, >5x = Great, >10x = Excellent!
A14: Monthly Contribution Margin | B14: =(Assumptions!B4)+(Assumptions!B18*Assumptions!B11) | C14: Profit per user per month
A15: Payback Period (months) | B15: =B4/B14 | C15: <6 months = Good, <3 months = Great!
A17: ANNUAL PROJECTIONS
A18: Annual Revenue (12 months) | B18: =Calculations!B9*12 | C18: Yearly top-line projection
A19: Annual Margin (12 months) | B19: =Calculations!B14*12 | C19: Yearly profit projection
A20: Annual Store Value Created | B20: =Calculations!B33*12*Assumptions!B36*1.15 | C20: Yearly value driven to partner stores

Sheet Sensitivity Analysis
A1: SENSITIVITY ANALYSIS
A3: SENSITIVITY: Monthly Ad Views per User
A4: EXPLANATION: This table shows how your business performs if users watch MORE or FEWER ads per month.
A5: Higher engagement = More ad revenue & rewards. Watch the margin % - it stays stable because rewards scale with views.
A7: Ad Views | B7: Revenue | C7: Margin | D7: Margin % | E7: User Rewards
A8: 3 | B8: 7600 | C8: 5440 | D8: 0.71578947 | E8: 0.36
A9: 6 | B9: 11200 | C9: 6880 | D9: 0.61428571 | E9: 0.72
A10: 9 | B10: 14800 | C10: 8320 | D10: 0.56216216 | E10: 1.08
A11: 12 | B11: 18400 | C11: 9760 | D11: 0.53043478 | E11: 1.44
A12: 15 | B12: 22000 | C12: 11200 | D12: 0.50909091 | E12: 1.8
A13: 18 | B13: 25600 | C13: 12640 | D13: 0.49375 | E13: 2.16
A14: 20 | B14: 28000 | C14: 13600 | D14: 0.48571429 | E14: 2.4
A15: 25 | B15: 34000 | C15: 16000 | D15: 0.47058824 | E15: 3
A18: SENSITIVITY: Bag Retail Price
A19: EXPLANATION: What happens if you price bags higher or lower? Higher price = more upfront revenue but may reduce volume.
A20: Key metric: User Net Cost. Negative = FREE bags after rewards! Watch this to keep bags attractive to users.
A22: Bag Price | B22: Revenue | C22: Margin | D22: Margin % | E22: User Net Cost
A23: 0.25 | B23: 16900 | C23: 8260 | D23: 0.4887574 | E23: -0.11
A24: 0.3 | B24: 17400 | C24: 8760 | D24: 0.50344828 | E24: -0.06
A25: 0.35 | B25: 17900 | C25: 9260 | D25: 0.51731844 | E25: -0.01
A26: 0.4 | B26: 18400 | C26: 9760 | D26: 0.53043478 | E26: 0.04
A27: 0.45 | B27: 18900 | C27: 10260 | D27: 0.54285714 | E27: 0.09
A28: 0.5 | B28: 19400 | C28: 10760 | D28: 0.55463918 | E28: 0.14
A29: 0.6 | B29: 20400 | C29: 11760 | D29: 0.57647059 | E29: 0.24
A30: 0.75 | B30: 21900 | C30: 13260 | D30: 0.60547945 | E30: 0.39
A33: SENSITIVITY: Monthly Volume (Bags Sold)
A34: EXPLANATION: This shows your business at different scales - from small pilot (5K bags) to large scale (50K+ bags/month).
A35: Notice: Margin % stays constant! The model scales linearly. Store Value = traffic driven to partner stores (their revenue opportunity).
A37: Bags Sold | B37: Revenue | C37: Margin | D37: Margin % | E37: Store Value
A38: 5000 | B38: 9200 | C38: 4880 | D38: 0.53043478 | E38: 7740
A39: 7500 | B39: 13800 | C39: 7320 | D39: 0.53043478 | E39: 11610
A40: 10000 | B40: 18400 | C40: 9760 | D40: 0.53043478 | E40: 15480
A41: 15000 | B41: 27600 | C41: 14640 | D41: 0.53043478 | E41: 23220
A42: 20000 | B42: 36800 | C42: 19520 | D42: 0.53043478 | E42: 30960
A43: 25000 | B43: 46000 | C43: 24400 | D43: 0.53043478 | E43: 38700
A44: 50000 | B44: 92000 | C44: 48800 | D44: 0.53043478 | E44: 77400

Sheet Visual Comparisons
A1: VISUAL COMPARISONS & INSIGHTS
A3: BRAND COST COMPARISON: Kshipra vs Meta
A4: Platform | B4: CPM | C4: Cost per Engagement
A5: Kshipra BagBuddy | B5: =Calculations!B39 | C5: =Calculations!B40 | D5: 100% verified engagement
A6: Meta/Facebook | B6: =Calculations!B44 | C6: =Calculations!B46 | D6: Only 1% CTR (99% wasted)
A19: USER VALUE: How Users Get FREE Bags
A20: Component | B20: Amount
A21: Bag Price (Paid Upfront) | B21: =Assumptions!B4 | C21: What user pays
A22: Cash Rewards Earned | B22: =-Assumptions!B17*Assumptions!B9 | C22: Instant cash back
A23: Store Credit Earned | B23: =-Assumptions!B17*Assumptions!B10 | C23: Redeemable rewards
A24: Net Cost to User | B24: =Calculations!B28 | C24: Negative = FREE!
A37: INVESTOR ATTRACTIVENESS
A38: Metric | B38: Value | C38: Target | D38: Rating
A39: LTV:CAC Ratio | B39: =(12*(Assumptions!B4+Assumptions!B18*Assumptions!B11))/2 | C39: >3x | D39: ✅ EXCELLENT
A40: Payback Period | B40: =2/(Assumptions!B4+Assumptions!B18*Assumptions!B11) | C40: <6 months | D40: ✅ EXCELLENT
A41: Margin % | B41: =Calculations!B14/Calculations!B9 | C41: >30% | D41: ✅ STRONG
A43: VALUE TO PARTNER STORES
A44: Metric | B44: Monthly Value
A45: Reward Redemptions | B45: =Calculations!B31*Assumptions!B33/100 | C45: Direct traffic to stores
A46: Baseline Basket Value | B46: =Calculations!B34 | C46: Standard purchases
A47: Incremental Basket Uplift | B47: =Calculations!B34*Assumptions!B35/100 | C47: Extra sales from rewards

Sheet References & Data Sources
A1: REFERENCES & DATA SOURCES
A3: All assumptions in this model are based on verified industry data and published research.
A5: SOCIAL MEDIA ADVERTISING COSTS
A6: Metric | B6: Value Used | C6: Source | D6: Year
A7: Meta/Facebook CPM | B7: $10.00 | C7: Meta Business Help Center, WordStream Benchmark Report | D7: 2024-2025
A8: TikTok CPM | B8: $8.50 | C8: TikTok Business, Social Media Examiner | D8: 2024
A9: Industry Average CTR | B9: 1.0% | C9: Facebook Ads Benchmarks by WordStream, HubSpot | D9: 2024
A10: Note: Actual CPMs vary by industry, targeting, and season. E-commerce typically $7-15.
A12: CONSUMER BEHAVIOR & ENGAGEMENT
A13: Metric | B13: Value Used | C13: Source | D13: Year
A14: Active User Rate | B14: 60% | C14: Industry avg for reward programs (Bond Brand Loyalty Report) | D14: 2024
A15: Reward Redemption Rate | B15: 75% | C15: Collinson Group Loyalty Census, COLLOQUY | D15: 2023-2024
A16: Basket Size Uplift | B16: 8% | C16: Accenture Strategy: Rewards Program Impact Study | D16: 2023
A17: Repeat Visit Increase | B17: 15% | C17: Harvard Business Review: The Value of Keeping the Right Customers | D17: 2023
A19: INVESTOR METRICS BENCHMARKS
A20: Metric | B20: Good Target | C20: Source | D20: Industry Standard
A21: LTV:CAC Ratio | B21: >3:1 | C21: SaaS Capital, Pacific Crest SaaS Survey | D21: 3:1 = Good, 5:1 = Great, >10:1 = Excellent
A22: CAC Payback Period | B22: <6 months | C22: KeyBanc Capital Markets, OpenView Partners | D22: <6mo = Good, <3mo = Excellent
A23: Customer Lifetime | B23: 12 months | C23: Industry avg for consumer apps (Mixpanel, Amplitude) | D23: 6-18 months typical range
A24: Gross Margin % | B24: >30% | C24: SaaS benchmarks (though we're marketplace model) | D24: 40-50% typical for tech platforms
A26: KEY RESEARCH & REPORTS
A27: Source | B27: URL | C27: Description
A28: Meta Business Help Center | B28: https://www.facebook.com/business/help | C28: Official Facebook/Meta advertising documentation
A29: WordStream Ad Benchmarks | B29: https://www.wordstream.com/blog/ws/2022/03/21/facebook-ad-benchmarks | C29: Industry CPM and CTR benchmarks
A30: Bond Brand Loyalty Report | B30: https://bondbrandloyalty.com/reports/ | C30: Annual loyalty program engagement statistics
A31: Collinson Loyalty Census | B31: https://www.collinsongroup.com/ | C31: Global loyalty program redemption rates
A32: HubSpot Marketing Statistics | B32: https://www.hubspot.com/marketing-statistics | C32: Social media CTR benchmarks
A33: SaaS Capital Survey | B33: https://www.saas-capital.com/ | C33: LTV:CAC and SaaS metrics benchmarks
A34: Pacific Crest SaaS Survey | B34: https://www.bvp.com/atlas/ | C34: Annual SaaS company metrics (via BVP)
A35: Accenture Strategy | B35: https://www.accenture.com/ | C35: Retail loyalty program impact studies
A38: METHODOLOGY NOTES
A39: 1. All financial projections are conservative estimates based on current market data.
A40: 2. CPM values represent median industry benchmarks; actual costs vary by targeting and competition.
A41: 3. User engagement rates (60% active) account for natural drop-off in reward program participation.
A42: 4. Redemption rates (75%) align with high-performing grocery/retail loyalty programs.
A43: 5. Basket uplift (8%) is conservative compared to industry average of 10-15% for reward-driven purchases.
A44: 6. Kshipra's verified engagement model eliminates ad fraud and bot traffic common in digital advertising.
A45: 7. Traditional social media CTR of 1% means brands waste 99% of impression budget on non-engaged users.
A46: 8. Our model assumes brands value verified engagement 20x higher than unverified impressions.
